<?xml version="1.0" encoding="UTF-8"?>
<!-- Generated by org.testng.reporters.JUnitXMLReporter -->
<testsuite hostname="Z100697" name="Default test" tests="9" failures="9" timestamp="23 Aug 2012 06:27:36 GMT" time="834.532" errors="0">
  <testcase name="@AfterClass tearDown" time="0.0" classname="com.exit.tests.Administrator">
    <failure type="com.thoughtworks.selenium.SeleniumException" message="ERROR Server Exception: sessionId eeb8a5d7b70e4d5a839b9b37a639fa9d doesn&amp;apos;t exist; perhaps this session was already stopped?">
      <![CDATA[com.thoughtworks.selenium.SeleniumException: ERROR Server Exception: sessionId eeb8a5d7b70e4d5a839b9b37a639fa9d doesn't exist; perhaps this session was already stopped?
	at com.thoughtworks.selenium.HttpCommandProcessor.throwAssertionFailureExceptionOrError(HttpCommandProcessor.java:112)
	at com.thoughtworks.selenium.HttpCommandProcessor.doCommand(HttpCommandProcessor.java:106)
	at com.unitedinternet.portal.selenium.utils.logging.LoggingCommandProcessor.doCommand(LoggingCommandProcessor.java:141)
	at com.thoughtworks.selenium.DefaultSelenium.close(DefaultSelenium.java:427)
	at com.test.fw.SeleniumHelper.dismissSelenium(SeleniumHelper.java:79)
	at com.exit.tests.TestBaseExit.tearDown(TestBaseExit.java:28)
	at sun.reflect.NativeMethodAccessorImpl.invoke0(Native Method)
	at sun.reflect.NativeMethodAccessorImpl.invoke(Unknown Source)
	at sun.reflect.DelegatingMethodAccessorImpl.invoke(Unknown Source)
	at java.lang.reflect.Method.invoke(Unknown Source)
	at org.testng.internal.MethodInvocationHelper.invokeMethod(MethodInvocationHelper.java:80)
	at org.testng.internal.Invoker.invokeConfigurationMethod(Invoker.java:564)
	at org.testng.internal.Invoker.invokeConfigurations(Invoker.java:213)
	at org.testng.internal.Invoker.invokeConfigurations(Invoker.java:138)
	at org.testng.internal.TestMethodWorker.invokeAfterClassMethods(TestMethodWorker.java:225)
	at org.testng.internal.TestMethodWorker.run(TestMethodWorker.java:114)
	at org.testng.TestRunner.privateRun(TestRunner.java:767)
	at org.testng.TestRunner.run(TestRunner.java:617)
	at org.testng.SuiteRunner.runTest(SuiteRunner.java:334)
	at org.testng.SuiteRunner.runSequentially(SuiteRunner.java:329)
	at org.testng.SuiteRunner.privateRun(SuiteRunner.java:291)
	at org.testng.SuiteRunner.run(SuiteRunner.java:240)
	at org.testng.SuiteRunnerWorker.runSuite(SuiteRunnerWorker.java:52)
	at org.testng.SuiteRunnerWorker.run(SuiteRunnerWorker.java:86)
	at org.testng.TestNG.runSuitesSequentially(TestNG.java:1197)
	at org.testng.TestNG.runSuitesLocally(TestNG.java:1122)
	at org.testng.TestNG.run(TestNG.java:1030)
	at org.testng.remote.RemoteTestNG.run(RemoteTestNG.java:111)
	at org.testng.remote.RemoteTestNG.initAndRun(RemoteTestNG.java:204)
	at org.testng.remote.RemoteTestNG.main(RemoteTestNG.java:175)
]]>
    </failure>
  </testcase> <!-- @AfterClass tearDown -->
  <testcase name="testwarning1" time="2.153" classname="com.exit.tests.Administrator">
    <failure type="com.thoughtworks.selenium.SeleniumException" message="ERROR Server Exception: unexpected command json={command:&amp;quot;open&amp;quot;,target:&amp;quot;http://umagicpro-pp/&amp;quot;,value:&amp;quot;&amp;quot;} in place before new command open could be added">
      <![CDATA[com.thoughtworks.selenium.SeleniumException: ERROR Server Exception: unexpected command json={command:"open",target:"http://umagicpro-pp/",value:""} in place before new command open could be added
	at com.thoughtworks.selenium.HttpCommandProcessor.throwAssertionFailureExceptionOrError(HttpCommandProcessor.java:112)
	at com.thoughtworks.selenium.HttpCommandProcessor.doCommand(HttpCommandProcessor.java:106)
	at com.unitedinternet.portal.selenium.utils.logging.LoggingCommandProcessor.doCommand(LoggingCommandProcessor.java:141)
	at com.thoughtworks.selenium.DefaultSelenium.open(DefaultSelenium.java:369)
	at com.exit.tests.Administrator.testwarning1(Administrator.java:13)
	at sun.reflect.NativeMethodAccessorImpl.invoke0(Native Method)
	at sun.reflect.NativeMethodAccessorImpl.invoke(Unknown Source)
	at sun.reflect.DelegatingMethodAccessorImpl.invoke(Unknown Source)
	at java.lang.reflect.Method.invoke(Unknown Source)
	at org.testng.internal.MethodInvocationHelper.invokeMethod(MethodInvocationHelper.java:80)
	at org.testng.internal.Invoker.invokeMethod(Invoker.java:714)
	at org.testng.internal.Invoker.invokeTestMethod(Invoker.java:901)
	at org.testng.internal.TestMethodWithDataProviderMethodWorker.call(TestMethodWithDataProviderMethodWorker.java:73)
	at org.testng.internal.TestMethodWithDataProviderMethodWorker.call(TestMethodWithDataProviderMethodWorker.java:14)
	at java.util.concurrent.FutureTask$Sync.innerRun(Unknown Source)
	at java.util.concurrent.FutureTask.run(Unknown Source)
	at java.util.concurrent.Executors$RunnableAdapter.call(Unknown Source)
	at java.util.concurrent.FutureTask$Sync.innerRun(Unknown Source)
	at java.util.concurrent.FutureTask.run(Unknown Source)
	at java.util.concurrent.ThreadPoolExecutor.runWorker(Unknown Source)
	at java.util.concurrent.ThreadPoolExecutor$Worker.run(Unknown Source)
	at java.lang.Thread.run(Unknown Source)
]]>
    </failure>
  </testcase> <!-- testwarning1 -->
  <testcase name="testwarning1" time="796.151" classname="com.exit.tests.Administrator">
    <failure type="com.thoughtworks.selenium.SeleniumException" message="Connection refused: connect">
      <![CDATA[com.thoughtworks.selenium.SeleniumException: Connection refused: connect
	at com.thoughtworks.selenium.HttpCommandProcessor.executeCommandOnServlet(HttpCommandProcessor.java:121)
	at com.thoughtworks.selenium.HttpCommandProcessor.doCommand(HttpCommandProcessor.java:101)
	at com.unitedinternet.portal.selenium.utils.logging.LoggingCommandProcessor.doCommand(LoggingCommandProcessor.java:141)
	at com.unitedinternet.portal.selenium.utils.logging.LoggingCommandProcessor.doAutomaticScreenshot(LoggingCommandProcessor.java:494)
	at com.unitedinternet.portal.selenium.utils.logging.LoggingCommandProcessor.doExceptionLogging(LoggingCommandProcessor.java:386)
	at com.unitedinternet.portal.selenium.utils.logging.LoggingCommandProcessor.doCommand(LoggingCommandProcessor.java:143)
	at com.thoughtworks.selenium.DefaultSelenium.open(DefaultSelenium.java:369)
	at com.exit.tests.Administrator.testwarning1(Administrator.java:13)
	at sun.reflect.NativeMethodAccessorImpl.invoke0(Native Method)
	at sun.reflect.NativeMethodAccessorImpl.invoke(Unknown Source)
	at sun.reflect.DelegatingMethodAccessorImpl.invoke(Unknown Source)
	at java.lang.reflect.Method.invoke(Unknown Source)
	at org.testng.internal.MethodInvocationHelper.invokeMethod(MethodInvocationHelper.java:80)
	at org.testng.internal.Invoker.invokeMethod(Invoker.java:714)
	at org.testng.internal.Invoker.invokeTestMethod(Invoker.java:901)
	at org.testng.internal.TestMethodWithDataProviderMethodWorker.call(TestMethodWithDataProviderMethodWorker.java:73)
	at org.testng.internal.TestMethodWithDataProviderMethodWorker.call(TestMethodWithDataProviderMethodWorker.java:14)
	at java.util.concurrent.FutureTask$Sync.innerRun(Unknown Source)
	at java.util.concurrent.FutureTask.run(Unknown Source)
	at java.util.concurrent.Executors$RunnableAdapter.call(Unknown Source)
	at java.util.concurrent.FutureTask$Sync.innerRun(Unknown Source)
	at java.util.concurrent.FutureTask.run(Unknown Source)
	at java.util.concurrent.ThreadPoolExecutor.runWorker(Unknown Source)
	at java.util.concurrent.ThreadPoolExecutor$Worker.run(Unknown Source)
	at java.lang.Thread.run(Unknown Source)
Caused by: java.net.ConnectException: Connection refused: connect
	at java.net.DualStackPlainSocketImpl.connect0(Native Method)
	at java.net.DualStackPlainSocketImpl.socketConnect(Unknown Source)
	at java.net.AbstractPlainSocketImpl.doConnect(Unknown Source)
	at java.net.AbstractPlainSocketImpl.connectToAddress(Unknown Source)
	at java.net.AbstractPlainSocketImpl.connect(Unknown Source)
	at java.net.PlainSocketImpl.connect(Unknown Source)
	at java.net.SocksSocketImpl.connect(Unknown Source)
	at java.net.Socket.connect(Unknown Source)
	at java.net.Socket.connect(Unknown Source)
	at sun.net.NetworkClient.doConnect(Unknown Source)
	at sun.net.www.http.HttpClient.openServer(Unknown Source)
	at sun.net.www.http.HttpClient.openServer(Unknown Source)
	at sun.net.www.http.HttpClient.<init>(Unknown Source)
	at sun.net.www.http.HttpClient.New(Unknown Source)
	at sun.net.www.http.HttpClient.New(Unknown Source)
	at sun.net.www.protocol.http.HttpURLConnection.getNewHttpClient(Unknown Source)
	at sun.net.www.protocol.http.HttpURLConnection.plainConnect(Unknown Source)
	at sun.net.www.protocol.http.HttpURLConnection.connect(Unknown Source)
	at sun.net.www.protocol.http.HttpURLConnection.getOutputStream(Unknown Source)
	at com.thoughtworks.selenium.HttpCommandProcessor.getOutputStreamWriter(HttpCommandProcessor.java:149)
	at com.thoughtworks.selenium.HttpCommandProcessor.getCommandResponseAsString(HttpCommandProcessor.java:176)
	at com.thoughtworks.selenium.HttpCommandProcessor.executeCommandOnServlet(HttpCommandProcessor.java:118)
	... 24 more
]]>
    </failure>
  </testcase> <!-- testwarning1 -->
  <testcase name="testwarning1" time="796.19" classname="com.exit.tests.Administrator">
    <failure type="com.thoughtworks.selenium.SeleniumException" message="Connection refused: connect">
      <![CDATA[com.thoughtworks.selenium.SeleniumException: Connection refused: connect
	at com.thoughtworks.selenium.HttpCommandProcessor.executeCommandOnServlet(HttpCommandProcessor.java:121)
	at com.thoughtworks.selenium.HttpCommandProcessor.doCommand(HttpCommandProcessor.java:101)
	at com.unitedinternet.portal.selenium.utils.logging.LoggingCommandProcessor.doCommand(LoggingCommandProcessor.java:141)
	at com.unitedinternet.portal.selenium.utils.logging.LoggingCommandProcessor.doAutomaticScreenshot(LoggingCommandProcessor.java:494)
	at com.unitedinternet.portal.selenium.utils.logging.LoggingCommandProcessor.doExceptionLogging(LoggingCommandProcessor.java:386)
	at com.unitedinternet.portal.selenium.utils.logging.LoggingCommandProcessor.doCommand(LoggingCommandProcessor.java:143)
	at com.thoughtworks.selenium.DefaultSelenium.open(DefaultSelenium.java:369)
	at com.exit.tests.Administrator.testwarning1(Administrator.java:13)
	at sun.reflect.NativeMethodAccessorImpl.invoke0(Native Method)
	at sun.reflect.NativeMethodAccessorImpl.invoke(Unknown Source)
	at sun.reflect.DelegatingMethodAccessorImpl.invoke(Unknown Source)
	at java.lang.reflect.Method.invoke(Unknown Source)
	at org.testng.internal.MethodInvocationHelper.invokeMethod(MethodInvocationHelper.java:80)
	at org.testng.internal.Invoker.invokeMethod(Invoker.java:714)
	at org.testng.internal.Invoker.invokeTestMethod(Invoker.java:901)
	at org.testng.internal.TestMethodWithDataProviderMethodWorker.call(TestMethodWithDataProviderMethodWorker.java:73)
	at org.testng.internal.TestMethodWithDataProviderMethodWorker.call(TestMethodWithDataProviderMethodWorker.java:14)
	at java.util.concurrent.FutureTask$Sync.innerRun(Unknown Source)
	at java.util.concurrent.FutureTask.run(Unknown Source)
	at java.util.concurrent.Executors$RunnableAdapter.call(Unknown Source)
	at java.util.concurrent.FutureTask$Sync.innerRun(Unknown Source)
	at java.util.concurrent.FutureTask.run(Unknown Source)
	at java.util.concurrent.ThreadPoolExecutor.runWorker(Unknown Source)
	at java.util.concurrent.ThreadPoolExecutor$Worker.run(Unknown Source)
	at java.lang.Thread.run(Unknown Source)
Caused by: java.net.ConnectException: Connection refused: connect
	at java.net.DualStackPlainSocketImpl.connect0(Native Method)
	at java.net.DualStackPlainSocketImpl.socketConnect(Unknown Source)
	at java.net.AbstractPlainSocketImpl.doConnect(Unknown Source)
	at java.net.AbstractPlainSocketImpl.connectToAddress(Unknown Source)
	at java.net.AbstractPlainSocketImpl.connect(Unknown Source)
	at java.net.PlainSocketImpl.connect(Unknown Source)
	at java.net.SocksSocketImpl.connect(Unknown Source)
	at java.net.Socket.connect(Unknown Source)
	at java.net.Socket.connect(Unknown Source)
	at sun.net.NetworkClient.doConnect(Unknown Source)
	at sun.net.www.http.HttpClient.openServer(Unknown Source)
	at sun.net.www.http.HttpClient.openServer(Unknown Source)
	at sun.net.www.http.HttpClient.<init>(Unknown Source)
	at sun.net.www.http.HttpClient.New(Unknown Source)
	at sun.net.www.http.HttpClient.New(Unknown Source)
	at sun.net.www.protocol.http.HttpURLConnection.getNewHttpClient(Unknown Source)
	at sun.net.www.protocol.http.HttpURLConnection.plainConnect(Unknown Source)
	at sun.net.www.protocol.http.HttpURLConnection.connect(Unknown Source)
	at sun.net.www.protocol.http.HttpURLConnection.getOutputStream(Unknown Source)
	at com.thoughtworks.selenium.HttpCommandProcessor.getOutputStreamWriter(HttpCommandProcessor.java:149)
	at com.thoughtworks.selenium.HttpCommandProcessor.getCommandResponseAsString(HttpCommandProcessor.java:176)
	at com.thoughtworks.selenium.HttpCommandProcessor.executeCommandOnServlet(HttpCommandProcessor.java:118)
	... 24 more
]]>
    </failure>
  </testcase> <!-- testwarning1 -->
  <testcase name="testwarning2" time="0.925" classname="com.exit.tests.Administrator">
    <failure type="com.thoughtworks.selenium.SeleniumException" message="ERROR Server Exception: sessionId eeb8a5d7b70e4d5a839b9b37a639fa9d doesn&amp;apos;t exist; perhaps this session was already stopped?">
      <![CDATA[com.thoughtworks.selenium.SeleniumException: ERROR Server Exception: sessionId eeb8a5d7b70e4d5a839b9b37a639fa9d doesn't exist; perhaps this session was already stopped?
	at com.thoughtworks.selenium.HttpCommandProcessor.throwAssertionFailureExceptionOrError(HttpCommandProcessor.java:112)
	at com.thoughtworks.selenium.HttpCommandProcessor.doCommand(HttpCommandProcessor.java:106)
	at com.unitedinternet.portal.selenium.utils.logging.LoggingCommandProcessor.doCommand(LoggingCommandProcessor.java:141)
	at com.thoughtworks.selenium.DefaultSelenium.open(DefaultSelenium.java:369)
	at com.exit.tests.Administrator.testwarning2(Administrator.java:30)
	at sun.reflect.NativeMethodAccessorImpl.invoke0(Native Method)
	at sun.reflect.NativeMethodAccessorImpl.invoke(Unknown Source)
	at sun.reflect.DelegatingMethodAccessorImpl.invoke(Unknown Source)
	at java.lang.reflect.Method.invoke(Unknown Source)
	at org.testng.internal.MethodInvocationHelper.invokeMethod(MethodInvocationHelper.java:80)
	at org.testng.internal.Invoker.invokeMethod(Invoker.java:714)
	at org.testng.internal.Invoker.invokeTestMethod(Invoker.java:901)
	at org.testng.internal.TestMethodWithDataProviderMethodWorker.call(TestMethodWithDataProviderMethodWorker.java:73)
	at org.testng.internal.TestMethodWithDataProviderMethodWorker.call(TestMethodWithDataProviderMethodWorker.java:14)
	at java.util.concurrent.FutureTask$Sync.innerRun(Unknown Source)
	at java.util.concurrent.FutureTask.run(Unknown Source)
	at java.util.concurrent.Executors$RunnableAdapter.call(Unknown Source)
	at java.util.concurrent.FutureTask$Sync.innerRun(Unknown Source)
	at java.util.concurrent.FutureTask.run(Unknown Source)
	at java.util.concurrent.ThreadPoolExecutor.runWorker(Unknown Source)
	at java.util.concurrent.ThreadPoolExecutor$Worker.run(Unknown Source)
	at java.lang.Thread.run(Unknown Source)
]]>
    </failure>
  </testcase> <!-- testwarning2 -->
  <testcase name="testwarning2" time="0.938" classname="com.exit.tests.Administrator">
    <failure type="com.thoughtworks.selenium.SeleniumException" message="ERROR Server Exception: sessionId eeb8a5d7b70e4d5a839b9b37a639fa9d doesn&amp;apos;t exist; perhaps this session was already stopped?">
      <![CDATA[com.thoughtworks.selenium.SeleniumException: ERROR Server Exception: sessionId eeb8a5d7b70e4d5a839b9b37a639fa9d doesn't exist; perhaps this session was already stopped?
	at com.thoughtworks.selenium.HttpCommandProcessor.throwAssertionFailureExceptionOrError(HttpCommandProcessor.java:112)
	at com.thoughtworks.selenium.HttpCommandProcessor.doCommand(HttpCommandProcessor.java:106)
	at com.unitedinternet.portal.selenium.utils.logging.LoggingCommandProcessor.doCommand(LoggingCommandProcessor.java:141)
	at com.thoughtworks.selenium.DefaultSelenium.open(DefaultSelenium.java:369)
	at com.exit.tests.Administrator.testwarning2(Administrator.java:30)
	at sun.reflect.NativeMethodAccessorImpl.invoke0(Native Method)
	at sun.reflect.NativeMethodAccessorImpl.invoke(Unknown Source)
	at sun.reflect.DelegatingMethodAccessorImpl.invoke(Unknown Source)
	at java.lang.reflect.Method.invoke(Unknown Source)
	at org.testng.internal.MethodInvocationHelper.invokeMethod(MethodInvocationHelper.java:80)
	at org.testng.internal.Invoker.invokeMethod(Invoker.java:714)
	at org.testng.internal.Invoker.invokeTestMethod(Invoker.java:901)
	at org.testng.internal.TestMethodWithDataProviderMethodWorker.call(TestMethodWithDataProviderMethodWorker.java:73)
	at org.testng.internal.TestMethodWithDataProviderMethodWorker.call(TestMethodWithDataProviderMethodWorker.java:14)
	at java.util.concurrent.FutureTask$Sync.innerRun(Unknown Source)
	at java.util.concurrent.FutureTask.run(Unknown Source)
	at java.util.concurrent.Executors$RunnableAdapter.call(Unknown Source)
	at java.util.concurrent.FutureTask$Sync.innerRun(Unknown Source)
	at java.util.concurrent.FutureTask.run(Unknown Source)
	at java.util.concurrent.ThreadPoolExecutor.runWorker(Unknown Source)
	at java.util.concurrent.ThreadPoolExecutor$Worker.run(Unknown Source)
	at java.lang.Thread.run(Unknown Source)
]]>
    </failure>
  </testcase> <!-- testwarning2 -->
  <testcase name="testRestorPassFalse" time="1.131" classname="com.exit.tests.Administrator">
    <failure type="com.thoughtworks.selenium.SeleniumException" message="ERROR Server Exception: sessionId eeb8a5d7b70e4d5a839b9b37a639fa9d doesn&amp;apos;t exist; perhaps this session was already stopped?">
      <![CDATA[com.thoughtworks.selenium.SeleniumException: ERROR Server Exception: sessionId eeb8a5d7b70e4d5a839b9b37a639fa9d doesn't exist; perhaps this session was already stopped?
	at com.thoughtworks.selenium.HttpCommandProcessor.throwAssertionFailureExceptionOrError(HttpCommandProcessor.java:112)
	at com.thoughtworks.selenium.HttpCommandProcessor.doCommand(HttpCommandProcessor.java:106)
	at com.unitedinternet.portal.selenium.utils.logging.LoggingCommandProcessor.doCommand(LoggingCommandProcessor.java:141)
	at com.thoughtworks.selenium.DefaultSelenium.open(DefaultSelenium.java:369)
	at com.exit.tests.Administrator.testRestorPassFalse(Administrator.java:47)
	at sun.reflect.NativeMethodAccessorImpl.invoke0(Native Method)
	at sun.reflect.NativeMethodAccessorImpl.invoke(Unknown Source)
	at sun.reflect.DelegatingMethodAccessorImpl.invoke(Unknown Source)
	at java.lang.reflect.Method.invoke(Unknown Source)
	at org.testng.internal.MethodInvocationHelper.invokeMethod(MethodInvocationHelper.java:80)
	at org.testng.internal.Invoker.invokeMethod(Invoker.java:714)
	at org.testng.internal.Invoker.invokeTestMethod(Invoker.java:901)
	at org.testng.internal.TestMethodWithDataProviderMethodWorker.call(TestMethodWithDataProviderMethodWorker.java:73)
	at org.testng.internal.TestMethodWithDataProviderMethodWorker.call(TestMethodWithDataProviderMethodWorker.java:14)
	at java.util.concurrent.FutureTask$Sync.innerRun(Unknown Source)
	at java.util.concurrent.FutureTask.run(Unknown Source)
	at java.util.concurrent.Executors$RunnableAdapter.call(Unknown Source)
	at java.util.concurrent.FutureTask$Sync.innerRun(Unknown Source)
	at java.util.concurrent.FutureTask.run(Unknown Source)
	at java.util.concurrent.ThreadPoolExecutor.runWorker(Unknown Source)
	at java.util.concurrent.ThreadPoolExecutor$Worker.run(Unknown Source)
	at java.lang.Thread.run(Unknown Source)
]]>
    </failure>
  </testcase> <!-- testRestorPassFalse -->
  <testcase name="testRestorPassFalse" time="1.148" classname="com.exit.tests.Administrator">
    <failure type="com.thoughtworks.selenium.SeleniumException" message="ERROR Server Exception: sessionId eeb8a5d7b70e4d5a839b9b37a639fa9d doesn&amp;apos;t exist; perhaps this session was already stopped?">
      <![CDATA[com.thoughtworks.selenium.SeleniumException: ERROR Server Exception: sessionId eeb8a5d7b70e4d5a839b9b37a639fa9d doesn't exist; perhaps this session was already stopped?
	at com.thoughtworks.selenium.HttpCommandProcessor.throwAssertionFailureExceptionOrError(HttpCommandProcessor.java:112)
	at com.thoughtworks.selenium.HttpCommandProcessor.doCommand(HttpCommandProcessor.java:106)
	at com.unitedinternet.portal.selenium.utils.logging.LoggingCommandProcessor.doCommand(LoggingCommandProcessor.java:141)
	at com.thoughtworks.selenium.DefaultSelenium.open(DefaultSelenium.java:369)
	at com.exit.tests.Administrator.testRestorPassFalse(Administrator.java:47)
	at sun.reflect.NativeMethodAccessorImpl.invoke0(Native Method)
	at sun.reflect.NativeMethodAccessorImpl.invoke(Unknown Source)
	at sun.reflect.DelegatingMethodAccessorImpl.invoke(Unknown Source)
	at java.lang.reflect.Method.invoke(Unknown Source)
	at org.testng.internal.MethodInvocationHelper.invokeMethod(MethodInvocationHelper.java:80)
	at org.testng.internal.Invoker.invokeMethod(Invoker.java:714)
	at org.testng.internal.Invoker.invokeTestMethod(Invoker.java:901)
	at org.testng.internal.TestMethodWithDataProviderMethodWorker.call(TestMethodWithDataProviderMethodWorker.java:73)
	at org.testng.internal.TestMethodWithDataProviderMethodWorker.call(TestMethodWithDataProviderMethodWorker.java:14)
	at java.util.concurrent.FutureTask$Sync.innerRun(Unknown Source)
	at java.util.concurrent.FutureTask.run(Unknown Source)
	at java.util.concurrent.Executors$RunnableAdapter.call(Unknown Source)
	at java.util.concurrent.FutureTask$Sync.innerRun(Unknown Source)
	at java.util.concurrent.FutureTask.run(Unknown Source)
	at java.util.concurrent.ThreadPoolExecutor.runWorker(Unknown Source)
	at java.util.concurrent.ThreadPoolExecutor$Worker.run(Unknown Source)
	at java.lang.Thread.run(Unknown Source)
]]>
    </failure>
  </testcase> <!-- testRestorPassFalse -->
  <testcase name="testRestorPassTrue" time="0.699" classname="com.exit.tests.Administrator">
    <failure type="com.thoughtworks.selenium.SeleniumException" message="ERROR Server Exception: sessionId eeb8a5d7b70e4d5a839b9b37a639fa9d doesn&amp;apos;t exist; perhaps this session was already stopped?">
      <![CDATA[com.thoughtworks.selenium.SeleniumException: ERROR Server Exception: sessionId eeb8a5d7b70e4d5a839b9b37a639fa9d doesn't exist; perhaps this session was already stopped?
	at com.thoughtworks.selenium.HttpCommandProcessor.throwAssertionFailureExceptionOrError(HttpCommandProcessor.java:112)
	at com.thoughtworks.selenium.HttpCommandProcessor.doCommand(HttpCommandProcessor.java:106)
	at com.unitedinternet.portal.selenium.utils.logging.LoggingCommandProcessor.doCommand(LoggingCommandProcessor.java:141)
	at com.thoughtworks.selenium.DefaultSelenium.open(DefaultSelenium.java:369)
	at com.exit.tests.Administrator.testRestorPassTrue(Administrator.java:72)
	at sun.reflect.NativeMethodAccessorImpl.invoke0(Native Method)
	at sun.reflect.NativeMethodAccessorImpl.invoke(Unknown Source)
	at sun.reflect.DelegatingMethodAccessorImpl.invoke(Unknown Source)
	at java.lang.reflect.Method.invoke(Unknown Source)
	at org.testng.internal.MethodInvocationHelper.invokeMethod(MethodInvocationHelper.java:80)
	at org.testng.internal.Invoker.invokeMethod(Invoker.java:714)
	at org.testng.internal.Invoker.invokeTestMethod(Invoker.java:901)
	at org.testng.internal.TestMethodWithDataProviderMethodWorker.call(TestMethodWithDataProviderMethodWorker.java:73)
	at org.testng.internal.TestMethodWithDataProviderMethodWorker.call(TestMethodWithDataProviderMethodWorker.java:14)
	at java.util.concurrent.FutureTask$Sync.innerRun(Unknown Source)
	at java.util.concurrent.FutureTask.run(Unknown Source)
	at java.util.concurrent.Executors$RunnableAdapter.call(Unknown Source)
	at java.util.concurrent.FutureTask$Sync.innerRun(Unknown Source)
	at java.util.concurrent.FutureTask.run(Unknown Source)
	at java.util.concurrent.ThreadPoolExecutor.runWorker(Unknown Source)
	at java.util.concurrent.ThreadPoolExecutor$Worker.run(Unknown Source)
	at java.lang.Thread.run(Unknown Source)
]]>
    </failure>
  </testcase> <!-- testRestorPassTrue -->
  <testcase name="testRestorPassTrue" time="0.82" classname="com.exit.tests.Administrator">
    <failure type="com.thoughtworks.selenium.SeleniumException" message="ERROR Server Exception: sessionId eeb8a5d7b70e4d5a839b9b37a639fa9d doesn&amp;apos;t exist; perhaps this session was already stopped?">
      <![CDATA[com.thoughtworks.selenium.SeleniumException: ERROR Server Exception: sessionId eeb8a5d7b70e4d5a839b9b37a639fa9d doesn't exist; perhaps this session was already stopped?
	at com.thoughtworks.selenium.HttpCommandProcessor.throwAssertionFailureExceptionOrError(HttpCommandProcessor.java:112)
	at com.thoughtworks.selenium.HttpCommandProcessor.doCommand(HttpCommandProcessor.java:106)
	at com.unitedinternet.portal.selenium.utils.logging.LoggingCommandProcessor.doCommand(LoggingCommandProcessor.java:141)
	at com.thoughtworks.selenium.DefaultSelenium.open(DefaultSelenium.java:369)
	at com.exit.tests.Administrator.testRestorPassTrue(Administrator.java:72)
	at sun.reflect.NativeMethodAccessorImpl.invoke0(Native Method)
	at sun.reflect.NativeMethodAccessorImpl.invoke(Unknown Source)
	at sun.reflect.DelegatingMethodAccessorImpl.invoke(Unknown Source)
	at java.lang.reflect.Method.invoke(Unknown Source)
	at org.testng.internal.MethodInvocationHelper.invokeMethod(MethodInvocationHelper.java:80)
	at org.testng.internal.Invoker.invokeMethod(Invoker.java:714)
	at org.testng.internal.Invoker.invokeTestMethod(Invoker.java:901)
	at org.testng.internal.TestMethodWithDataProviderMethodWorker.call(TestMethodWithDataProviderMethodWorker.java:73)
	at org.testng.internal.TestMethodWithDataProviderMethodWorker.call(TestMethodWithDataProviderMethodWorker.java:14)
	at java.util.concurrent.FutureTask$Sync.innerRun(Unknown Source)
	at java.util.concurrent.FutureTask.run(Unknown Source)
	at java.util.concurrent.Executors$RunnableAdapter.call(Unknown Source)
	at java.util.concurrent.FutureTask$Sync.innerRun(Unknown Source)
	at java.util.concurrent.FutureTask.run(Unknown Source)
	at java.util.concurrent.ThreadPoolExecutor.runWorker(Unknown Source)
	at java.util.concurrent.ThreadPoolExecutor$Worker.run(Unknown Source)
	at java.lang.Thread.run(Unknown Source)
]]>
    </failure>
  </testcase> <!-- testRestorPassTrue -->
</testsuite> <!-- Default test -->
