<?xml version="1.0" encoding="UTF-8"?>
<testng-results skipped="0" failed="2" total="2" passed="0">
  <reporter-output>
  </reporter-output>
  <suite name="Default suite" duration-ms="125808" started-at="2012-08-13T14:16:33Z" finished-at="2012-08-13T14:18:39Z">
    <groups>
    </groups>
    <test name="Default test" duration-ms="125808" started-at="2012-08-13T14:16:33Z" finished-at="2012-08-13T14:18:39Z">
      <class name="com.exit.tests.Administrator">
        <test-method status="PASS" signature="setUp(java.lang.String)[pri:0, instance:com.exit.tests.Administrator@1844b009]" name="setUp" is-config="true" duration-ms="19795" started-at="2012-08-13T18:16:33Z" finished-at="2012-08-13T18:16:53Z">
          <params>
            <param index="0">
              <value is-null="true"/>
            </param>
          </params>
          <reporter-output>
          </reporter-output>
        </test-method> <!-- setUp -->
        <test-method status="FAIL" signature="testRestorPassTrue(java.lang.String)[pri:0, instance:com.exit.tests.Administrator@1844b009]" name="testRestorPassTrue" duration-ms="92716" started-at="2012-08-13T18:16:53Z" data-provider="restorPassTrue" finished-at="2012-08-13T18:18:26Z">
          <params>
            <param index="0">
              <value>
                <![CDATA[100102]]>
              </value>
            </param>
          </params>
          <exception class="java.lang.AssertionError">
            <message>
              <![CDATA[timeout перехода по ссылки из письма]]>
            </message>
            <full-stacktrace>
              <![CDATA[java.lang.AssertionError: timeout перехода по ссылки из письма
	at org.testng.AssertJUnit.fail(AssertJUnit.java:59)
	at com.exit.tests.Administrator.testRestorPassTrue(Administrator.java:127)
	at sun.reflect.NativeMethodAccessorImpl.invoke0(Native Method)
	at sun.reflect.NativeMethodAccessorImpl.invoke(Unknown Source)
	at sun.reflect.DelegatingMethodAccessorImpl.invoke(Unknown Source)
	at java.lang.reflect.Method.invoke(Unknown Source)
	at org.testng.internal.MethodInvocationHelper.invokeMethod(MethodInvocationHelper.java:80)
	at org.testng.internal.Invoker.invokeMethod(Invoker.java:715)
	at org.testng.internal.Invoker.invokeTestMethod(Invoker.java:907)
	at org.testng.internal.Invoker.invokeTestMethods(Invoker.java:1237)
	at org.testng.internal.TestMethodWorker.invokeTestMethods(TestMethodWorker.java:127)
	at org.testng.internal.TestMethodWorker.run(TestMethodWorker.java:111)
	at org.testng.TestRunner.privateRun(TestRunner.java:767)
	at org.testng.TestRunner.run(TestRunner.java:617)
	at org.testng.SuiteRunner.runTest(SuiteRunner.java:334)
	at org.testng.SuiteRunner.runSequentially(SuiteRunner.java:329)
	at org.testng.SuiteRunner.privateRun(SuiteRunner.java:291)
	at org.testng.SuiteRunner.run(SuiteRunner.java:240)
	at org.testng.SuiteRunnerWorker.runSuite(SuiteRunnerWorker.java:51)
	at org.testng.SuiteRunnerWorker.run(SuiteRunnerWorker.java:85)
	at org.testng.TestNG.runSuitesSequentially(TestNG.java:1197)
	at org.testng.TestNG.runSuitesLocally(TestNG.java:1122)
	at org.testng.TestNG.run(TestNG.java:1030)
	at org.testng.remote.RemoteTestNG.run(RemoteTestNG.java:111)
	at org.testng.remote.RemoteTestNG.initAndRun(RemoteTestNG.java:204)
	at org.testng.remote.RemoteTestNG.main(RemoteTestNG.java:175)
]]>
            </full-stacktrace>
          </exception> <!-- java.lang.AssertionError -->
          <reporter-output>
          </reporter-output>
        </test-method> <!-- testRestorPassTrue -->
        <test-method status="FAIL" signature="testRestorPassTrue(java.lang.String)[pri:0, instance:com.exit.tests.Administrator@1844b009]" name="testRestorPassTrue" duration-ms="5816" started-at="2012-08-13T18:18:26Z" data-provider="restorPassTrue" finished-at="2012-08-13T18:18:31Z">
          <params>
            <param index="0">
              <value>
                <![CDATA[SqaTest@yandex.ru]]>
              </value>
            </param>
          </params>
          <exception class="com.thoughtworks.selenium.SeleniumException">
            <message>
              <![CDATA[ERROR: Element id=b-mail-domik-username11 not found]]>
            </message>
            <full-stacktrace>
              <![CDATA[com.thoughtworks.selenium.SeleniumException: ERROR: Element id=b-mail-domik-username11 not found
	at com.thoughtworks.selenium.HttpCommandProcessor.throwAssertionFailureExceptionOrError(HttpCommandProcessor.java:112)
	at com.thoughtworks.selenium.HttpCommandProcessor.doCommand(HttpCommandProcessor.java:106)
	at com.unitedinternet.portal.selenium.utils.logging.LoggingCommandProcessor.doCommand(LoggingCommandProcessor.java:141)
	at com.thoughtworks.selenium.DefaultSelenium.type(DefaultSelenium.java:317)
	at com.exit.tests.Administrator.testRestorPassTrue(Administrator.java:91)
	at sun.reflect.NativeMethodAccessorImpl.invoke0(Native Method)
	at sun.reflect.NativeMethodAccessorImpl.invoke(Unknown Source)
	at sun.reflect.DelegatingMethodAccessorImpl.invoke(Unknown Source)
	at java.lang.reflect.Method.invoke(Unknown Source)
	at org.testng.internal.MethodInvocationHelper.invokeMethod(MethodInvocationHelper.java:80)
	at org.testng.internal.Invoker.invokeMethod(Invoker.java:715)
	at org.testng.internal.Invoker.invokeTestMethod(Invoker.java:907)
	at org.testng.internal.Invoker.invokeTestMethods(Invoker.java:1237)
	at org.testng.internal.TestMethodWorker.invokeTestMethods(TestMethodWorker.java:127)
	at org.testng.internal.TestMethodWorker.run(TestMethodWorker.java:111)
	at org.testng.TestRunner.privateRun(TestRunner.java:767)
	at org.testng.TestRunner.run(TestRunner.java:617)
	at org.testng.SuiteRunner.runTest(SuiteRunner.java:334)
	at org.testng.SuiteRunner.runSequentially(SuiteRunner.java:329)
	at org.testng.SuiteRunner.privateRun(SuiteRunner.java:291)
	at org.testng.SuiteRunner.run(SuiteRunner.java:240)
	at org.testng.SuiteRunnerWorker.runSuite(SuiteRunnerWorker.java:51)
	at org.testng.SuiteRunnerWorker.run(SuiteRunnerWorker.java:85)
	at org.testng.TestNG.runSuitesSequentially(TestNG.java:1197)
	at org.testng.TestNG.runSuitesLocally(TestNG.java:1122)
	at org.testng.TestNG.run(TestNG.java:1030)
	at org.testng.remote.RemoteTestNG.run(RemoteTestNG.java:111)
	at org.testng.remote.RemoteTestNG.initAndRun(RemoteTestNG.java:204)
	at org.testng.remote.RemoteTestNG.main(RemoteTestNG.java:175)
]]>
            </full-stacktrace>
          </exception> <!-- com.thoughtworks.selenium.SeleniumException -->
          <reporter-output>
          </reporter-output>
        </test-method> <!-- testRestorPassTrue -->
        <test-method status="PASS" signature="tearDown()[pri:0, instance:com.exit.tests.Administrator@1844b009]" name="tearDown" is-config="true" duration-ms="7465" started-at="2012-08-13T18:18:31Z" finished-at="2012-08-13T18:18:39Z">
          <reporter-output>
          </reporter-output>
        </test-method> <!-- tearDown -->
      </class> <!-- com.exit.tests.Administrator -->
    </test> <!-- Default test -->
  </suite> <!-- Default suite -->
</testng-results>
