<?xml version="1.0" encoding="UTF-8"?>
<!-- Generated by org.testng.reporters.JUnitReportReporter -->
<testsuite hostname="Z100697" name="com.registration.tests.Step1" tests="11" failures="11" timestamp="23 Aug 2012 06:27:35 GMT" time="450.565" errors="0">
  <testcase name="testStep1" time="219.548" classname="com.registration.tests.Step1">
    <failure type="com.thoughtworks.selenium.SeleniumException" message="Connection refused: connect">
      <![CDATA[com.thoughtworks.selenium.SeleniumException: Connection refused: connect
	at com.thoughtworks.selenium.HttpCommandProcessor.executeCommandOnServlet(HttpCommandProcessor.java:121)
	at com.thoughtworks.selenium.HttpCommandProcessor.doCommand(HttpCommandProcessor.java:101)
	at com.unitedinternet.portal.selenium.utils.logging.LoggingCommandProcessor.doCommand(LoggingCommandProcessor.java:141)
	at com.unitedinternet.portal.selenium.utils.logging.LoggingCommandProcessor.doAutomaticScreenshot(LoggingCommandProcessor.java:494)
	at com.unitedinternet.portal.selenium.utils.logging.LoggingCommandProcessor.doExceptionLogging(LoggingCommandProcessor.java:386)
	at com.unitedinternet.portal.selenium.utils.logging.LoggingCommandProcessor.doCommand(LoggingCommandProcessor.java:143)
	at com.thoughtworks.selenium.DefaultSelenium.open(DefaultSelenium.java:369)
	at com.registration.tests.Step1.testStep1(Step1.java:11)
	at sun.reflect.NativeMethodAccessorImpl.invoke0(Native Method)
	at sun.reflect.NativeMethodAccessorImpl.invoke(Unknown Source)
	at sun.reflect.DelegatingMethodAccessorImpl.invoke(Unknown Source)
	at java.lang.reflect.Method.invoke(Unknown Source)
	at org.testng.internal.MethodInvocationHelper.invokeMethod(MethodInvocationHelper.java:80)
	at org.testng.internal.Invoker.invokeMethod(Invoker.java:714)
	at org.testng.internal.Invoker.invokeTestMethod(Invoker.java:901)
	at org.testng.internal.TestMethodWithDataProviderMethodWorker.call(TestMethodWithDataProviderMethodWorker.java:73)
	at org.testng.internal.TestMethodWithDataProviderMethodWorker.call(TestMethodWithDataProviderMethodWorker.java:14)
	at java.util.concurrent.FutureTask$Sync.innerRun(Unknown Source)
	at java.util.concurrent.FutureTask.run(Unknown Source)
	at java.util.concurrent.Executors$RunnableAdapter.call(Unknown Source)
	at java.util.concurrent.FutureTask$Sync.innerRun(Unknown Source)
	at java.util.concurrent.FutureTask.run(Unknown Source)
	at java.util.concurrent.ThreadPoolExecutor.runWorker(Unknown Source)
	at java.util.concurrent.ThreadPoolExecutor$Worker.run(Unknown Source)
	at java.lang.Thread.run(Unknown Source)
Caused by: java.net.ConnectException: Connection refused: connect
	at java.net.DualStackPlainSocketImpl.connect0(Native Method)
	at java.net.DualStackPlainSocketImpl.socketConnect(Unknown Source)
	at java.net.AbstractPlainSocketImpl.doConnect(Unknown Source)
	at java.net.AbstractPlainSocketImpl.connectToAddress(Unknown Source)
	at java.net.AbstractPlainSocketImpl.connect(Unknown Source)
	at java.net.PlainSocketImpl.connect(Unknown Source)
	at java.net.SocksSocketImpl.connect(Unknown Source)
	at java.net.Socket.connect(Unknown Source)
	at java.net.Socket.connect(Unknown Source)
	at sun.net.NetworkClient.doConnect(Unknown Source)
	at sun.net.www.http.HttpClient.openServer(Unknown Source)
	at sun.net.www.http.HttpClient.openServer(Unknown Source)
	at sun.net.www.http.HttpClient.<init>(Unknown Source)
	at sun.net.www.http.HttpClient.New(Unknown Source)
	at sun.net.www.http.HttpClient.New(Unknown Source)
	at sun.net.www.protocol.http.HttpURLConnection.getNewHttpClient(Unknown Source)
	at sun.net.www.protocol.http.HttpURLConnection.plainConnect(Unknown Source)
	at sun.net.www.protocol.http.HttpURLConnection.connect(Unknown Source)
	at sun.net.www.protocol.http.HttpURLConnection.getOutputStream(Unknown Source)
	at com.thoughtworks.selenium.HttpCommandProcessor.getOutputStreamWriter(HttpCommandProcessor.java:149)
	at com.thoughtworks.selenium.HttpCommandProcessor.getCommandResponseAsString(HttpCommandProcessor.java:176)
	at com.thoughtworks.selenium.HttpCommandProcessor.executeCommandOnServlet(HttpCommandProcessor.java:118)
	... 24 more
]]>
    </failure>
  </testcase> <!-- testStep1 -->
  <testcase name="testStep1" time="1.246" classname="com.registration.tests.Step1">
    <failure type="com.thoughtworks.selenium.SeleniumException" message="ERROR Server Exception: unexpected command json={command:&quot;open&quot;,target:&quot;http://umagicpro-pp/&quot;,value:&quot;&quot;} in place before new command open could be added">
      <![CDATA[com.thoughtworks.selenium.SeleniumException: ERROR Server Exception: unexpected command json={command:"open",target:"http://umagicpro-pp/",value:""} in place before new command open could be added
	at com.thoughtworks.selenium.HttpCommandProcessor.throwAssertionFailureExceptionOrError(HttpCommandProcessor.java:112)
	at com.thoughtworks.selenium.HttpCommandProcessor.doCommand(HttpCommandProcessor.java:106)
	at com.unitedinternet.portal.selenium.utils.logging.LoggingCommandProcessor.doCommand(LoggingCommandProcessor.java:141)
	at com.thoughtworks.selenium.DefaultSelenium.open(DefaultSelenium.java:369)
	at com.registration.tests.Step1.testStep1(Step1.java:11)
	at sun.reflect.NativeMethodAccessorImpl.invoke0(Native Method)
	at sun.reflect.NativeMethodAccessorImpl.invoke(Unknown Source)
	at sun.reflect.DelegatingMethodAccessorImpl.invoke(Unknown Source)
	at java.lang.reflect.Method.invoke(Unknown Source)
	at org.testng.internal.MethodInvocationHelper.invokeMethod(MethodInvocationHelper.java:80)
	at org.testng.internal.Invoker.invokeMethod(Invoker.java:714)
	at org.testng.internal.Invoker.invokeTestMethod(Invoker.java:901)
	at org.testng.internal.TestMethodWithDataProviderMethodWorker.call(TestMethodWithDataProviderMethodWorker.java:73)
	at org.testng.internal.TestMethodWithDataProviderMethodWorker.call(TestMethodWithDataProviderMethodWorker.java:14)
	at java.util.concurrent.FutureTask$Sync.innerRun(Unknown Source)
	at java.util.concurrent.FutureTask.run(Unknown Source)
	at java.util.concurrent.Executors$RunnableAdapter.call(Unknown Source)
	at java.util.concurrent.FutureTask$Sync.innerRun(Unknown Source)
	at java.util.concurrent.FutureTask.run(Unknown Source)
	at java.util.concurrent.ThreadPoolExecutor.runWorker(Unknown Source)
	at java.util.concurrent.ThreadPoolExecutor$Worker.run(Unknown Source)
	at java.lang.Thread.run(Unknown Source)
]]>
    </failure>
  </testcase> <!-- testStep1 -->
  <testcase name="testStep1Find" time="0.828" classname="com.registration.tests.Step1">
    <failure type="com.thoughtworks.selenium.SeleniumException" message="ERROR Server Exception: sessionId f14122836b3e493a8ce5f7da038be18d doesn&#039;t exist; perhaps this session was already stopped?">
      <![CDATA[com.thoughtworks.selenium.SeleniumException: ERROR Server Exception: sessionId f14122836b3e493a8ce5f7da038be18d doesn't exist; perhaps this session was already stopped?
	at com.thoughtworks.selenium.HttpCommandProcessor.throwAssertionFailureExceptionOrError(HttpCommandProcessor.java:112)
	at com.thoughtworks.selenium.HttpCommandProcessor.doCommand(HttpCommandProcessor.java:106)
	at com.thoughtworks.selenium.HttpCommandProcessor.getString(HttpCommandProcessor.java:275)
	at com.thoughtworks.selenium.HttpCommandProcessor.getBoolean(HttpCommandProcessor.java:348)
	at com.unitedinternet.portal.selenium.utils.logging.LoggingCommandProcessor.getBoolean(LoggingCommandProcessor.java:168)
	at com.thoughtworks.selenium.DefaultSelenium.isAlertPresent(DefaultSelenium.java:431)
	at com.registration.tests.Step1.testStep1Find(Step1.java:36)
	at sun.reflect.NativeMethodAccessorImpl.invoke0(Native Method)
	at sun.reflect.NativeMethodAccessorImpl.invoke(Unknown Source)
	at sun.reflect.DelegatingMethodAccessorImpl.invoke(Unknown Source)
	at java.lang.reflect.Method.invoke(Unknown Source)
	at org.testng.internal.MethodInvocationHelper.invokeMethod(MethodInvocationHelper.java:80)
	at org.testng.internal.Invoker.invokeMethod(Invoker.java:714)
	at org.testng.internal.Invoker.invokeTestMethod(Invoker.java:901)
	at org.testng.internal.TestMethodWithDataProviderMethodWorker.call(TestMethodWithDataProviderMethodWorker.java:73)
	at org.testng.internal.TestMethodWithDataProviderMethodWorker.call(TestMethodWithDataProviderMethodWorker.java:14)
	at java.util.concurrent.FutureTask$Sync.innerRun(Unknown Source)
	at java.util.concurrent.FutureTask.run(Unknown Source)
	at java.util.concurrent.Executors$RunnableAdapter.call(Unknown Source)
	at java.util.concurrent.FutureTask$Sync.innerRun(Unknown Source)
	at java.util.concurrent.FutureTask.run(Unknown Source)
	at java.util.concurrent.ThreadPoolExecutor.runWorker(Unknown Source)
	at java.util.concurrent.ThreadPoolExecutor$Worker.run(Unknown Source)
	at java.lang.Thread.run(Unknown Source)
]]>
    </failure>
  </testcase> <!-- testStep1Find -->
  <testcase name="testStep1" time="1.608" classname="com.registration.tests.Step1">
    <failure type="com.thoughtworks.selenium.SeleniumException" message="ERROR Server Exception: unexpected command json={command:&quot;open&quot;,target:&quot;http://umagicpro-pp/&quot;,value:&quot;&quot;} in place before new command open could be added">
      <![CDATA[com.thoughtworks.selenium.SeleniumException: ERROR Server Exception: unexpected command json={command:"open",target:"http://umagicpro-pp/",value:""} in place before new command open could be added
	at com.thoughtworks.selenium.HttpCommandProcessor.throwAssertionFailureExceptionOrError(HttpCommandProcessor.java:112)
	at com.thoughtworks.selenium.HttpCommandProcessor.doCommand(HttpCommandProcessor.java:106)
	at com.unitedinternet.portal.selenium.utils.logging.LoggingCommandProcessor.doCommand(LoggingCommandProcessor.java:141)
	at com.thoughtworks.selenium.DefaultSelenium.open(DefaultSelenium.java:369)
	at com.registration.tests.Step1.testStep1(Step1.java:11)
	at sun.reflect.NativeMethodAccessorImpl.invoke0(Native Method)
	at sun.reflect.NativeMethodAccessorImpl.invoke(Unknown Source)
	at sun.reflect.DelegatingMethodAccessorImpl.invoke(Unknown Source)
	at java.lang.reflect.Method.invoke(Unknown Source)
	at org.testng.internal.MethodInvocationHelper.invokeMethod(MethodInvocationHelper.java:80)
	at org.testng.internal.Invoker.invokeMethod(Invoker.java:714)
	at org.testng.internal.Invoker.invokeTestMethod(Invoker.java:901)
	at org.testng.internal.TestMethodWithDataProviderMethodWorker.call(TestMethodWithDataProviderMethodWorker.java:73)
	at org.testng.internal.TestMethodWithDataProviderMethodWorker.call(TestMethodWithDataProviderMethodWorker.java:14)
	at java.util.concurrent.FutureTask$Sync.innerRun(Unknown Source)
	at java.util.concurrent.FutureTask.run(Unknown Source)
	at java.util.concurrent.Executors$RunnableAdapter.call(Unknown Source)
	at java.util.concurrent.FutureTask$Sync.innerRun(Unknown Source)
	at java.util.concurrent.FutureTask.run(Unknown Source)
	at java.util.concurrent.ThreadPoolExecutor.runWorker(Unknown Source)
	at java.util.concurrent.ThreadPoolExecutor$Worker.run(Unknown Source)
	at java.lang.Thread.run(Unknown Source)
]]>
    </failure>
  </testcase> <!-- testStep1 -->
  <testcase name="testStep1" time="1.603" classname="com.registration.tests.Step1">
    <failure type="com.thoughtworks.selenium.SeleniumException" message="ERROR Server Exception: unexpected command json={command:&quot;open&quot;,target:&quot;http://umagicpro-pp/&quot;,value:&quot;&quot;} in place before new command open could be added">
      <![CDATA[com.thoughtworks.selenium.SeleniumException: ERROR Server Exception: unexpected command json={command:"open",target:"http://umagicpro-pp/",value:""} in place before new command open could be added
	at com.thoughtworks.selenium.HttpCommandProcessor.throwAssertionFailureExceptionOrError(HttpCommandProcessor.java:112)
	at com.thoughtworks.selenium.HttpCommandProcessor.doCommand(HttpCommandProcessor.java:106)
	at com.unitedinternet.portal.selenium.utils.logging.LoggingCommandProcessor.doCommand(LoggingCommandProcessor.java:141)
	at com.thoughtworks.selenium.DefaultSelenium.open(DefaultSelenium.java:369)
	at com.registration.tests.Step1.testStep1(Step1.java:11)
	at sun.reflect.NativeMethodAccessorImpl.invoke0(Native Method)
	at sun.reflect.NativeMethodAccessorImpl.invoke(Unknown Source)
	at sun.reflect.DelegatingMethodAccessorImpl.invoke(Unknown Source)
	at java.lang.reflect.Method.invoke(Unknown Source)
	at org.testng.internal.MethodInvocationHelper.invokeMethod(MethodInvocationHelper.java:80)
	at org.testng.internal.Invoker.invokeMethod(Invoker.java:714)
	at org.testng.internal.Invoker.invokeTestMethod(Invoker.java:901)
	at org.testng.internal.TestMethodWithDataProviderMethodWorker.call(TestMethodWithDataProviderMethodWorker.java:73)
	at org.testng.internal.TestMethodWithDataProviderMethodWorker.call(TestMethodWithDataProviderMethodWorker.java:14)
	at java.util.concurrent.FutureTask$Sync.innerRun(Unknown Source)
	at java.util.concurrent.FutureTask.run(Unknown Source)
	at java.util.concurrent.Executors$RunnableAdapter.call(Unknown Source)
	at java.util.concurrent.FutureTask$Sync.innerRun(Unknown Source)
	at java.util.concurrent.FutureTask.run(Unknown Source)
	at java.util.concurrent.ThreadPoolExecutor.runWorker(Unknown Source)
	at java.util.concurrent.ThreadPoolExecutor$Worker.run(Unknown Source)
	at java.lang.Thread.run(Unknown Source)
]]>
    </failure>
  </testcase> <!-- testStep1 -->
  <testcase name="testStep1" time="1.309" classname="com.registration.tests.Step1">
    <failure type="com.thoughtworks.selenium.SeleniumException" message="ERROR Server Exception: unexpected command json={command:&quot;open&quot;,target:&quot;http://umagicpro-pp/&quot;,value:&quot;&quot;} in place before new command open could be added">
      <![CDATA[com.thoughtworks.selenium.SeleniumException: ERROR Server Exception: unexpected command json={command:"open",target:"http://umagicpro-pp/",value:""} in place before new command open could be added
	at com.thoughtworks.selenium.HttpCommandProcessor.throwAssertionFailureExceptionOrError(HttpCommandProcessor.java:112)
	at com.thoughtworks.selenium.HttpCommandProcessor.doCommand(HttpCommandProcessor.java:106)
	at com.unitedinternet.portal.selenium.utils.logging.LoggingCommandProcessor.doCommand(LoggingCommandProcessor.java:141)
	at com.thoughtworks.selenium.DefaultSelenium.open(DefaultSelenium.java:369)
	at com.registration.tests.Step1.testStep1(Step1.java:11)
	at sun.reflect.NativeMethodAccessorImpl.invoke0(Native Method)
	at sun.reflect.NativeMethodAccessorImpl.invoke(Unknown Source)
	at sun.reflect.DelegatingMethodAccessorImpl.invoke(Unknown Source)
	at java.lang.reflect.Method.invoke(Unknown Source)
	at org.testng.internal.MethodInvocationHelper.invokeMethod(MethodInvocationHelper.java:80)
	at org.testng.internal.Invoker.invokeMethod(Invoker.java:714)
	at org.testng.internal.Invoker.invokeTestMethod(Invoker.java:901)
	at org.testng.internal.TestMethodWithDataProviderMethodWorker.call(TestMethodWithDataProviderMethodWorker.java:73)
	at org.testng.internal.TestMethodWithDataProviderMethodWorker.call(TestMethodWithDataProviderMethodWorker.java:14)
	at java.util.concurrent.FutureTask$Sync.innerRun(Unknown Source)
	at java.util.concurrent.FutureTask.run(Unknown Source)
	at java.util.concurrent.Executors$RunnableAdapter.call(Unknown Source)
	at java.util.concurrent.FutureTask$Sync.innerRun(Unknown Source)
	at java.util.concurrent.FutureTask.run(Unknown Source)
	at java.util.concurrent.ThreadPoolExecutor.runWorker(Unknown Source)
	at java.util.concurrent.ThreadPoolExecutor$Worker.run(Unknown Source)
	at java.lang.Thread.run(Unknown Source)
]]>
    </failure>
  </testcase> <!-- testStep1 -->
  <testcase name="testStep1" time="1.595" classname="com.registration.tests.Step1">
    <failure type="com.thoughtworks.selenium.SeleniumException" message="ERROR Server Exception: unexpected command json={command:&quot;open&quot;,target:&quot;http://umagicpro-pp/&quot;,value:&quot;&quot;} in place before new command open could be added">
      <![CDATA[com.thoughtworks.selenium.SeleniumException: ERROR Server Exception: unexpected command json={command:"open",target:"http://umagicpro-pp/",value:""} in place before new command open could be added
	at com.thoughtworks.selenium.HttpCommandProcessor.throwAssertionFailureExceptionOrError(HttpCommandProcessor.java:112)
	at com.thoughtworks.selenium.HttpCommandProcessor.doCommand(HttpCommandProcessor.java:106)
	at com.unitedinternet.portal.selenium.utils.logging.LoggingCommandProcessor.doCommand(LoggingCommandProcessor.java:141)
	at com.thoughtworks.selenium.DefaultSelenium.open(DefaultSelenium.java:369)
	at com.registration.tests.Step1.testStep1(Step1.java:11)
	at sun.reflect.NativeMethodAccessorImpl.invoke0(Native Method)
	at sun.reflect.NativeMethodAccessorImpl.invoke(Unknown Source)
	at sun.reflect.DelegatingMethodAccessorImpl.invoke(Unknown Source)
	at java.lang.reflect.Method.invoke(Unknown Source)
	at org.testng.internal.MethodInvocationHelper.invokeMethod(MethodInvocationHelper.java:80)
	at org.testng.internal.Invoker.invokeMethod(Invoker.java:714)
	at org.testng.internal.Invoker.invokeTestMethod(Invoker.java:901)
	at org.testng.internal.TestMethodWithDataProviderMethodWorker.call(TestMethodWithDataProviderMethodWorker.java:73)
	at org.testng.internal.TestMethodWithDataProviderMethodWorker.call(TestMethodWithDataProviderMethodWorker.java:14)
	at java.util.concurrent.FutureTask$Sync.innerRun(Unknown Source)
	at java.util.concurrent.FutureTask.run(Unknown Source)
	at java.util.concurrent.Executors$RunnableAdapter.call(Unknown Source)
	at java.util.concurrent.FutureTask$Sync.innerRun(Unknown Source)
	at java.util.concurrent.FutureTask.run(Unknown Source)
	at java.util.concurrent.ThreadPoolExecutor.runWorker(Unknown Source)
	at java.util.concurrent.ThreadPoolExecutor$Worker.run(Unknown Source)
	at java.lang.Thread.run(Unknown Source)
]]>
    </failure>
  </testcase> <!-- testStep1 -->
  <testcase name="testStep1" time="1.415" classname="com.registration.tests.Step1">
    <failure type="com.thoughtworks.selenium.SeleniumException" message="ERROR Server Exception: unexpected command json={command:&quot;open&quot;,target:&quot;http://umagicpro-pp/&quot;,value:&quot;&quot;} in place before new command open could be added">
      <![CDATA[com.thoughtworks.selenium.SeleniumException: ERROR Server Exception: unexpected command json={command:"open",target:"http://umagicpro-pp/",value:""} in place before new command open could be added
	at com.thoughtworks.selenium.HttpCommandProcessor.throwAssertionFailureExceptionOrError(HttpCommandProcessor.java:112)
	at com.thoughtworks.selenium.HttpCommandProcessor.doCommand(HttpCommandProcessor.java:106)
	at com.unitedinternet.portal.selenium.utils.logging.LoggingCommandProcessor.doCommand(LoggingCommandProcessor.java:141)
	at com.thoughtworks.selenium.DefaultSelenium.open(DefaultSelenium.java:369)
	at com.registration.tests.Step1.testStep1(Step1.java:11)
	at sun.reflect.NativeMethodAccessorImpl.invoke0(Native Method)
	at sun.reflect.NativeMethodAccessorImpl.invoke(Unknown Source)
	at sun.reflect.DelegatingMethodAccessorImpl.invoke(Unknown Source)
	at java.lang.reflect.Method.invoke(Unknown Source)
	at org.testng.internal.MethodInvocationHelper.invokeMethod(MethodInvocationHelper.java:80)
	at org.testng.internal.Invoker.invokeMethod(Invoker.java:714)
	at org.testng.internal.Invoker.invokeTestMethod(Invoker.java:901)
	at org.testng.internal.TestMethodWithDataProviderMethodWorker.call(TestMethodWithDataProviderMethodWorker.java:73)
	at org.testng.internal.TestMethodWithDataProviderMethodWorker.call(TestMethodWithDataProviderMethodWorker.java:14)
	at java.util.concurrent.FutureTask$Sync.innerRun(Unknown Source)
	at java.util.concurrent.FutureTask.run(Unknown Source)
	at java.util.concurrent.Executors$RunnableAdapter.call(Unknown Source)
	at java.util.concurrent.FutureTask$Sync.innerRun(Unknown Source)
	at java.util.concurrent.FutureTask.run(Unknown Source)
	at java.util.concurrent.ThreadPoolExecutor.runWorker(Unknown Source)
	at java.util.concurrent.ThreadPoolExecutor$Worker.run(Unknown Source)
	at java.lang.Thread.run(Unknown Source)
]]>
    </failure>
  </testcase> <!-- testStep1 -->
  <testcase name="testStep1" time="219.452" classname="com.registration.tests.Step1">
    <failure type="com.thoughtworks.selenium.SeleniumException" message="Connection refused: connect">
      <![CDATA[com.thoughtworks.selenium.SeleniumException: Connection refused: connect
	at com.thoughtworks.selenium.HttpCommandProcessor.executeCommandOnServlet(HttpCommandProcessor.java:121)
	at com.thoughtworks.selenium.HttpCommandProcessor.doCommand(HttpCommandProcessor.java:101)
	at com.unitedinternet.portal.selenium.utils.logging.LoggingCommandProcessor.doCommand(LoggingCommandProcessor.java:141)
	at com.unitedinternet.portal.selenium.utils.logging.LoggingCommandProcessor.doAutomaticScreenshot(LoggingCommandProcessor.java:494)
	at com.unitedinternet.portal.selenium.utils.logging.LoggingCommandProcessor.doExceptionLogging(LoggingCommandProcessor.java:386)
	at com.unitedinternet.portal.selenium.utils.logging.LoggingCommandProcessor.doCommand(LoggingCommandProcessor.java:143)
	at com.unitedinternet.portal.selenium.utils.logging.LoggingCommandProcessor.doAutomaticScreenshot(LoggingCommandProcessor.java:494)
	at com.unitedinternet.portal.selenium.utils.logging.LoggingCommandProcessor.doExceptionLogging(LoggingCommandProcessor.java:386)
	at com.unitedinternet.portal.selenium.utils.logging.LoggingCommandProcessor.doCommand(LoggingCommandProcessor.java:143)
	at com.unitedinternet.portal.selenium.utils.logging.LoggingCommandProcessor.doAutomaticScreenshot(LoggingCommandProcessor.java:494)
	at com.unitedinternet.portal.selenium.utils.logging.LoggingCommandProcessor.doExceptionLogging(LoggingCommandProcessor.java:386)
	at com.unitedinternet.portal.selenium.utils.logging.LoggingCommandProcessor.doCommand(LoggingCommandProcessor.java:143)
	at com.unitedinternet.portal.selenium.utils.logging.LoggingCommandProcessor.doAutomaticScreenshot(LoggingCommandProcessor.java:494)
	at com.unitedinternet.portal.selenium.utils.logging.LoggingCommandProcessor.doExceptionLogging(LoggingCommandProcessor.java:386)
	at com.unitedinternet.portal.selenium.utils.logging.LoggingCommandProcessor.doCommand(LoggingCommandProcessor.java:143)
	at com.thoughtworks.selenium.DefaultSelenium.open(DefaultSelenium.java:369)
	at com.registration.tests.Step1.testStep1(Step1.java:11)
	at sun.reflect.NativeMethodAccessorImpl.invoke0(Native Method)
	at sun.reflect.NativeMethodAccessorImpl.invoke(Unknown Source)
	at sun.reflect.DelegatingMethodAccessorImpl.invoke(Unknown Source)
	at java.lang.reflect.Method.invoke(Unknown Source)
	at org.testng.internal.MethodInvocationHelper.invokeMethod(MethodInvocationHelper.java:80)
	at org.testng.internal.Invoker.invokeMethod(Invoker.java:714)
	at org.testng.internal.Invoker.invokeTestMethod(Invoker.java:901)
	at org.testng.internal.TestMethodWithDataProviderMethodWorker.call(TestMethodWithDataProviderMethodWorker.java:73)
	at org.testng.internal.TestMethodWithDataProviderMethodWorker.call(TestMethodWithDataProviderMethodWorker.java:14)
	at java.util.concurrent.FutureTask$Sync.innerRun(Unknown Source)
	at java.util.concurrent.FutureTask.run(Unknown Source)
	at java.util.concurrent.Executors$RunnableAdapter.call(Unknown Source)
	at java.util.concurrent.FutureTask$Sync.innerRun(Unknown Source)
	at java.util.concurrent.FutureTask.run(Unknown Source)
	at java.util.concurrent.ThreadPoolExecutor.runWorker(Unknown Source)
	at java.util.concurrent.ThreadPoolExecutor$Worker.run(Unknown Source)
	at java.lang.Thread.run(Unknown Source)
Caused by: java.net.ConnectException: Connection refused: connect
	at java.net.DualStackPlainSocketImpl.connect0(Native Method)
	at java.net.DualStackPlainSocketImpl.socketConnect(Unknown Source)
	at java.net.AbstractPlainSocketImpl.doConnect(Unknown Source)
	at java.net.AbstractPlainSocketImpl.connectToAddress(Unknown Source)
	at java.net.AbstractPlainSocketImpl.connect(Unknown Source)
	at java.net.PlainSocketImpl.connect(Unknown Source)
	at java.net.SocksSocketImpl.connect(Unknown Source)
	at java.net.Socket.connect(Unknown Source)
	at java.net.Socket.connect(Unknown Source)
	at sun.net.NetworkClient.doConnect(Unknown Source)
	at sun.net.www.http.HttpClient.openServer(Unknown Source)
	at sun.net.www.http.HttpClient.openServer(Unknown Source)
	at sun.net.www.http.HttpClient.<init>(Unknown Source)
	at sun.net.www.http.HttpClient.New(Unknown Source)
	at sun.net.www.http.HttpClient.New(Unknown Source)
	at sun.net.www.protocol.http.HttpURLConnection.getNewHttpClient(Unknown Source)
	at sun.net.www.protocol.http.HttpURLConnection.plainConnect(Unknown Source)
	at sun.net.www.protocol.http.HttpURLConnection.connect(Unknown Source)
	at sun.net.www.protocol.http.HttpURLConnection.getOutputStream(Unknown Source)
	at com.thoughtworks.selenium.HttpCommandProcessor.getOutputStreamWriter(HttpCommandProcessor.java:149)
	at com.thoughtworks.selenium.HttpCommandProcessor.getCommandResponseAsString(HttpCommandProcessor.java:176)
	at com.thoughtworks.selenium.HttpCommandProcessor.executeCommandOnServlet(HttpCommandProcessor.java:118)
	... 33 more
]]>
    </failure>
  </testcase> <!-- testStep1 -->
  <testcase name="testStep1Find" time="0.995" classname="com.registration.tests.Step1">
    <failure type="com.thoughtworks.selenium.SeleniumException" message="ERROR Server Exception: sessionId f14122836b3e493a8ce5f7da038be18d doesn&#039;t exist; perhaps this session was already stopped?">
      <![CDATA[com.thoughtworks.selenium.SeleniumException: ERROR Server Exception: sessionId f14122836b3e493a8ce5f7da038be18d doesn't exist; perhaps this session was already stopped?
	at com.thoughtworks.selenium.HttpCommandProcessor.throwAssertionFailureExceptionOrError(HttpCommandProcessor.java:112)
	at com.thoughtworks.selenium.HttpCommandProcessor.doCommand(HttpCommandProcessor.java:106)
	at com.thoughtworks.selenium.HttpCommandProcessor.getString(HttpCommandProcessor.java:275)
	at com.thoughtworks.selenium.HttpCommandProcessor.getBoolean(HttpCommandProcessor.java:348)
	at com.unitedinternet.portal.selenium.utils.logging.LoggingCommandProcessor.getBoolean(LoggingCommandProcessor.java:168)
	at com.thoughtworks.selenium.DefaultSelenium.isAlertPresent(DefaultSelenium.java:431)
	at com.registration.tests.Step1.testStep1Find(Step1.java:36)
	at sun.reflect.NativeMethodAccessorImpl.invoke0(Native Method)
	at sun.reflect.NativeMethodAccessorImpl.invoke(Unknown Source)
	at sun.reflect.DelegatingMethodAccessorImpl.invoke(Unknown Source)
	at java.lang.reflect.Method.invoke(Unknown Source)
	at org.testng.internal.MethodInvocationHelper.invokeMethod(MethodInvocationHelper.java:80)
	at org.testng.internal.Invoker.invokeMethod(Invoker.java:714)
	at org.testng.internal.Invoker.invokeTestMethod(Invoker.java:901)
	at org.testng.internal.TestMethodWithDataProviderMethodWorker.call(TestMethodWithDataProviderMethodWorker.java:73)
	at org.testng.internal.TestMethodWithDataProviderMethodWorker.call(TestMethodWithDataProviderMethodWorker.java:14)
	at java.util.concurrent.FutureTask$Sync.innerRun(Unknown Source)
	at java.util.concurrent.FutureTask.run(Unknown Source)
	at java.util.concurrent.Executors$RunnableAdapter.call(Unknown Source)
	at java.util.concurrent.FutureTask$Sync.innerRun(Unknown Source)
	at java.util.concurrent.FutureTask.run(Unknown Source)
	at java.util.concurrent.ThreadPoolExecutor.runWorker(Unknown Source)
	at java.util.concurrent.ThreadPoolExecutor$Worker.run(Unknown Source)
	at java.lang.Thread.run(Unknown Source)
]]>
    </failure>
  </testcase> <!-- testStep1Find -->
  <testcase name="testStep1Find" time="0.966" classname="com.registration.tests.Step1">
    <failure type="com.thoughtworks.selenium.SeleniumException" message="ERROR Server Exception: sessionId f14122836b3e493a8ce5f7da038be18d doesn&#039;t exist; perhaps this session was already stopped?">
      <![CDATA[com.thoughtworks.selenium.SeleniumException: ERROR Server Exception: sessionId f14122836b3e493a8ce5f7da038be18d doesn't exist; perhaps this session was already stopped?
	at com.thoughtworks.selenium.HttpCommandProcessor.throwAssertionFailureExceptionOrError(HttpCommandProcessor.java:112)
	at com.thoughtworks.selenium.HttpCommandProcessor.doCommand(HttpCommandProcessor.java:106)
	at com.thoughtworks.selenium.HttpCommandProcessor.getString(HttpCommandProcessor.java:275)
	at com.thoughtworks.selenium.HttpCommandProcessor.getBoolean(HttpCommandProcessor.java:348)
	at com.unitedinternet.portal.selenium.utils.logging.LoggingCommandProcessor.getBoolean(LoggingCommandProcessor.java:168)
	at com.thoughtworks.selenium.DefaultSelenium.isAlertPresent(DefaultSelenium.java:431)
	at com.registration.tests.Step1.testStep1Find(Step1.java:36)
	at sun.reflect.NativeMethodAccessorImpl.invoke0(Native Method)
	at sun.reflect.NativeMethodAccessorImpl.invoke(Unknown Source)
	at sun.reflect.DelegatingMethodAccessorImpl.invoke(Unknown Source)
	at java.lang.reflect.Method.invoke(Unknown Source)
	at org.testng.internal.MethodInvocationHelper.invokeMethod(MethodInvocationHelper.java:80)
	at org.testng.internal.Invoker.invokeMethod(Invoker.java:714)
	at org.testng.internal.Invoker.invokeTestMethod(Invoker.java:901)
	at org.testng.internal.TestMethodWithDataProviderMethodWorker.call(TestMethodWithDataProviderMethodWorker.java:73)
	at org.testng.internal.TestMethodWithDataProviderMethodWorker.call(TestMethodWithDataProviderMethodWorker.java:14)
	at java.util.concurrent.FutureTask$Sync.innerRun(Unknown Source)
	at java.util.concurrent.FutureTask.run(Unknown Source)
	at java.util.concurrent.Executors$RunnableAdapter.call(Unknown Source)
	at java.util.concurrent.FutureTask$Sync.innerRun(Unknown Source)
	at java.util.concurrent.FutureTask.run(Unknown Source)
	at java.util.concurrent.ThreadPoolExecutor.runWorker(Unknown Source)
	at java.util.concurrent.ThreadPoolExecutor$Worker.run(Unknown Source)
	at java.lang.Thread.run(Unknown Source)
]]>
    </failure>
  </testcase> <!-- testStep1Find -->
</testsuite> <!-- com.registration.tests.Step1 -->
